[2022-08-10 13:47:00,060] {taskinstance.py:1179} INFO - Dependencies all met for <TaskInstance: ml_model_etl.extract_data scheduled__2022-08-09T00:00:00+00:00 [queued]>
[2022-08-10 13:47:00,065] {taskinstance.py:1179} INFO - Dependencies all met for <TaskInstance: ml_model_etl.extract_data scheduled__2022-08-09T00:00:00+00:00 [queued]>
[2022-08-10 13:47:00,065] {taskinstance.py:1376} INFO - 
--------------------------------------------------------------------------------
[2022-08-10 13:47:00,065] {taskinstance.py:1377} INFO - Starting attempt 1 of 2
[2022-08-10 13:47:00,065] {taskinstance.py:1378} INFO - 
--------------------------------------------------------------------------------
[2022-08-10 13:47:00,093] {taskinstance.py:1397} INFO - Executing <Task(PythonOperator): extract_data> on 2022-08-09 00:00:00+00:00
[2022-08-10 13:47:00,102] {standard_task_runner.py:52} INFO - Started process 136441 to run task
[2022-08-10 13:47:00,108] {standard_task_runner.py:79} INFO - Running: ['airflow', 'tasks', 'run', 'ml_model_etl', 'extract_data', 'scheduled__2022-08-09T00:00:00+00:00', '--job-id', '43', '--raw', '--subdir', 'DAGS_FOLDER/ml_model_etl.py', '--cfg-path', '/tmp/tmprhr68h03', '--error-file', '/tmp/tmp3gb6_k92']
[2022-08-10 13:47:00,109] {standard_task_runner.py:80} INFO - Job 43: Subtask extract_data
[2022-08-10 13:47:00,164] {task_command.py:371} INFO - Running <TaskInstance: ml_model_etl.extract_data scheduled__2022-08-09T00:00:00+00:00 [running]> on host new-ThinkPad-L14-Gen-1
[2022-08-10 13:47:00,224] {taskinstance.py:1589} INFO - Exporting the following env vars:
AIRFLOW_CTX_DAG_OWNER=airflow
AIRFLOW_CTX_DAG_ID=ml_model_etl
AIRFLOW_CTX_TASK_ID=extract_data
AIRFLOW_CTX_EXECUTION_DATE=2022-08-09T00:00:00+00:00
AIRFLOW_CTX_TRY_NUMBER=1
AIRFLOW_CTX_DAG_RUN_ID=scheduled__2022-08-09T00:00:00+00:00
[2022-08-10 13:47:00,225] {taskinstance.py:1909} ERROR - Task failed with exception
Traceback (most recent call last):
  File "/home/new/anaconda3/lib/python3.8/site-packages/airflow/operators/python.py", line 171, in execute
    return_value = self.execute_callable()
  File "/home/new/anaconda3/lib/python3.8/site-packages/airflow/operators/python.py", line 189, in execute_callable
    return self.python_callable(*self.op_args, **self.op_kwargs)
  File "/home/new/airflow/dags/ml_model_etl.py", line 379, in extract
    df = pd.read_pickle("/opt/airflow/dags/repo/data/df.pkl")
  File "/home/new/anaconda3/lib/python3.8/site-packages/pandas/io/pickle.py", line 196, in read_pickle
    with get_handle(
  File "/home/new/anaconda3/lib/python3.8/site-packages/pandas/io/common.py", line 711, in get_handle
    handle = open(handle, ioargs.mode)
FileNotFoundError: [Errno 2] No such file or directory: '/opt/airflow/dags/repo/data/df.pkl'
[2022-08-10 13:47:00,228] {taskinstance.py:1415} INFO - Marking task as UP_FOR_RETRY. dag_id=ml_model_etl, task_id=extract_data, execution_date=20220809T000000, start_date=20220810T081700, end_date=20220810T081700
[2022-08-10 13:47:00,242] {standard_task_runner.py:92} ERROR - Failed to execute job 43 for task extract_data ([Errno 2] No such file or directory: '/opt/airflow/dags/repo/data/df.pkl'; 136441)
[2022-08-10 13:47:00,278] {local_task_job.py:156} INFO - Task exited with return code 1
[2022-08-10 13:47:00,316] {local_task_job.py:273} INFO - 0 downstream tasks scheduled from follow-on schedule check
